<?xml version="1.0"?>
<robot name="my robot">

    <link name="base_link">
        <visual>
            <geometry>
                <box size="0.5 0.2 0.1"/>
            </geometry>

            <origin xyz="0 0 0" rpy="0 0 0"/>
            <material name="green">
                <color rgba="0.7 0.5 1.0 0.5"/>
            </material>
        </visual>
    </link>    

    <link name="link1">
        <visual>
            <geometry>
                <cylinder radius="0.05" length="0.03"/>
            </geometry>

            <origin xyz="0 0 0" rpy="0 0.0 0.0"/>
            <material name="green">
                <color rgba="0.7 0.5 1.0 0.2"/>
                 
            </material>
        </visual>
    </link>  

    <joint name="joint1" type="continuous">
        <origin xyz="0.13 0.12 0.0" rpy="0.0 0.0 0.0"/>
        <parent link="base_link"/>
        <child link="link1"/>
        <axis xyz="0 1 0"/>  
    </joint>
    
</robot>